<sdf version='1.6'>
  <model name='human'>
    <link name='head'>
      <pose frame=''>0 0 0 0 -0 0</pose>
      <inertial>
        <pose frame=''>0.7 0.5 1.225 0 -0 0</pose>
        <mass>5</mass>
        <inertia>
          <ixx>0</ixx>
          <ixy>0</ixy>
          <ixz>0</ixz>
          <iyy>0</iyy>
          <iyz>0</iyz>
          <izz>0</izz>
        </inertia>
      </inertial>
      <collision name='head_collision'>
        <pose frame=''>0 0 0 0 -0 0</pose>
        <geometry>
          <sphere>
            <radius>0.05</radius>
          </sphere>
        </geometry>
      </collision>
      <visual name='head_visual'>
        <pose frame=''>0.7 0.5 1.225 0 -0 0</pose>
        <geometry>
          <sphere>
            <radius>0.05</radius>
          </sphere>
        </geometry>
      </visual>
    </link>
    <joint name='fixed' type='fixed'>
      <child>head</child>
      <parent>world</parent>
    </joint>
    <link name='neck'>
      <pose frame=''>0 0 0 0 -0 0</pose>
      <inertial>
        <pose frame=''>0.7 0.5 1.1625 0 -0 0</pose>
        <mass>2.5</mass>
        <inertia>
          <ixx>0</ixx>
          <ixy>0</ixy>
          <ixz>0</ixz>
          <iyy>0</iyy>
          <iyz>0</iyz>
          <izz>0</izz>
        </inertia>
      </inertial>
      <collision name='neck_collision'>
        <pose frame=''>0 0 0 0 -0 0</pose>
        <geometry>
          <cylinder>
            <length>0.025</length>
            <radius>0.025</radius>
          </cylinder>
        </geometry>
      </collision>
      <visual name='neck_visual'>
        <pose frame=''>0.7 0.5 1.1625 0 -0 0</pose>
        <geometry>
          <cylinder>
            <length>0.025</length>
            <radius>0.025</radius>
          </cylinder>
        </geometry>
      </visual>
    </link>
    <joint name='head_1' type='revolute'>
      <child>neck</child>
      <parent>head</parent>
      <axis>
        <xyz>1 0 0</xyz>
        <limit>
          <lower>-1e+16</lower>
          <upper>1e+16</upper>
        </limit>
        <dynamics>
          <spring_reference>0</spring_reference>
          <spring_stiffness>0</spring_stiffness>
        </dynamics>
        <use_parent_model_frame>1</use_parent_model_frame>
      </axis>
    </joint>
    <link name='torso'>
      <pose frame=''>0 0 0 0 -0 0</pose>
      <inertial>
        <pose frame=''>0.7 0.5 0.96 0 -0 0</pose>
        <mass>50</mass>
        <inertia>
          <ixx>0</ixx>
          <ixy>0</ixy>
          <ixz>0</ixz>
          <iyy>0</iyy>
          <iyz>0</iyz>
          <izz>0</izz>
        </inertia>
      </inertial>
      <collision name='torso_collision'>
        <pose frame=''>0 0 0 0 -0 0</pose>
        <geometry>
          <box>
            <size>0.15 0.15 0.375</size>
          </box>
        </geometry>
      </collision>
      <visual name='torso_visual'>
        <pose frame=''>0.7 0.5 0.96 0 -0 0</pose>
        <geometry>
          <box>
            <size>0.15 0.15 0.375</size>
          </box>
        </geometry>
      </visual>
    </link>
    <joint name='neck_2' type='revolute'>
      <child>torso</child>
      <parent>neck</parent>
      <axis>
        <xyz>1 0 0</xyz>
        <limit>
          <lower>-1e+16</lower>
          <upper>1e+16</upper>
        </limit>
        <dynamics>
          <spring_reference>0</spring_reference>
          <spring_stiffness>0</spring_stiffness>
        </dynamics>
        <use_parent_model_frame>1</use_parent_model_frame>
      </axis>
    </joint>
    <link name='left_hip'>
      <pose frame=''>0 0 0 0 -0 0</pose>
      <inertial>
        <pose frame=''>0.65 0.5 0.655 0 -0 0</pose>
        <mass>12.5</mass>
        <inertia>
          <ixx>0</ixx>
          <ixy>0</ixy>
          <ixz>0</ixz>
          <iyy>0</iyy>
          <iyz>0</iyz>
          <izz>0</izz>
        </inertia>
      </inertial>
      <collision name='left_hip_collision'>
        <pose frame=''>0 0 0 0 -0 0</pose>
        <geometry>
          <cylinder>
            <length>0.225</length>
            <radius>0.025</radius>
          </cylinder>
        </geometry>
      </collision>
      <visual name='left_hip_visual'>
        <pose frame=''>0.65 0.5 0.655 0 -0 0</pose>
        <geometry>
          <cylinder>
            <length>0.225</length>
            <radius>0.025</radius>
          </cylinder>
        </geometry>
      </visual>
    </link>
    <joint name='left_hip_1' type='revolute'>
      <child>left_hip</child>
      <parent>torso</parent>
      <axis>
        <xyz>1 0 0</xyz>
        <limit>
          <lower>-1e+16</lower>
          <upper>1e+16</upper>
        </limit>
        <dynamics>
          <spring_reference>0</spring_reference>
          <spring_stiffness>0</spring_stiffness>
        </dynamics>
        <use_parent_model_frame>1</use_parent_model_frame>
      </axis>
    </joint>
    <link name='left_knee'>
      <pose frame=''>0 0 0 0 -0 0</pose>
      <inertial>
        <pose frame=''>0.65 0.5 0.34 0 -0 0</pose>
        <mass>7.5</mass>
        <inertia>
          <ixx>0</ixx>
          <ixy>0</ixy>
          <ixz>0</ixz>
          <iyy>0</iyy>
          <iyz>0</iyz>
          <izz>0</izz>
        </inertia>
      </inertial>
      <collision name='left_knee_collision'>
        <pose frame=''>0 0 0 0 -0 0</pose>
        <geometry>
          <cylinder>
            <length>0.4</length>
            <radius>0.025</radius>
          </cylinder>
        </geometry>
      </collision>
      <visual name='left_knee_visual'>
        <pose frame=''>0.65 0.5 0.34 0 -0 0</pose>
        <geometry>
          <cylinder>
            <length>0.4</length>
            <radius>0.025</radius>
          </cylinder>
        </geometry>
      </visual>
    </link>
    <joint name='left_knee_1' type='revolute'>
      <child>left_knee</child>
      <parent>left_hip</parent>
      <axis>
        <xyz>1 0 0</xyz>
        <limit>
          <lower>-1e+16</lower>
          <upper>1e+16</upper>
        </limit>
        <dynamics>
          <spring_reference>0</spring_reference>
          <spring_stiffness>0</spring_stiffness>
        </dynamics>
        <use_parent_model_frame>1</use_parent_model_frame>
      </axis>
    </joint>
    <link name='left_foot'>
      <pose frame=''>0 0 0 0 -0 0</pose>
      <inertial>
        <pose frame=''>0.65 0.5 0.095 0 -0 0</pose>
        <mass>2.5</mass>
        <inertia>
          <ixx>0</ixx>
          <ixy>0</ixy>
          <ixz>0</ixz>
          <iyy>0</iyy>
          <iyz>0</iyz>
          <izz>0</izz>
        </inertia>
      </inertial>
      <collision name='left_foot_collision'>
        <pose frame=''>0 0 0 0 -0 0</pose>
        <geometry>
          <box>
            <size>0.02 0.02 0.08</size>
          </box>
        </geometry>
      </collision>
      <visual name='left_foot_visual'>
        <pose frame=''>0.65 0.5 0.095 0 -0 0</pose>
        <geometry>
          <box>
            <size>0.02 0.02 0.08</size>
          </box>
        </geometry>
      </visual>
    </link>
    <joint name='left_foot_1' type='revolute'>
      <child>left_foot</child>
      <parent>left_knee</parent>
      <axis>
        <xyz>1 0 0</xyz>
        <limit>
          <lower>-1e+16</lower>
          <upper>1e+16</upper>
        </limit>
        <dynamics>
          <spring_reference>0</spring_reference>
          <spring_stiffness>0</spring_stiffness>
        </dynamics>
        <use_parent_model_frame>1</use_parent_model_frame>
      </axis>
    </joint>
    <link name='left_shoulder'>
      <pose frame=''>0.595 0.5 1.1475 0 -0 0</pose>
      <inertial>
        <pose frame=''>0 0 -0.0625 0 -0 0</pose>
        <mass>12.5</mass>
        <inertia>
          <ixx>0</ixx>
          <ixy>0</ixy>
          <ixz>0</ixz>
          <iyy>0</iyy>
          <iyz>0</iyz>
          <izz>0</izz>
        </inertia>
      </inertial>
      <collision name='left_shoulder_collision'>
        <pose frame=''>0 0 0 0 -0 0</pose>
        <geometry>
          <cylinder>
            <length>0.125</length>
            <radius>0.025</radius>
          </cylinder>
        </geometry>
      </collision>
      <visual name='left_shoulder_visual'>
        <pose frame=''>0 0 -0.0625 0 -0 0</pose>
        <geometry>
          <cylinder>
            <length>0.125</length>
            <radius>0.025</radius>
          </cylinder>
        </geometry>
      </visual>
    </link>
    <joint name='left_shoulder_1' type='revolute'>
      <child>left_shoulder</child>
      <parent>torso</parent>
      <axis>
        <xyz>1 0 0</xyz>
        <limit>
          <lower>-3.14</lower>
          <upper>3.14</upper>
          <effort>30</effort>
          <velocity>1</velocity>
        </limit>
        <dynamics>
          <spring_reference>0</spring_reference>
          <spring_stiffness>0</spring_stiffness>
        </dynamics>
        <use_parent_model_frame>1</use_parent_model_frame>
      </axis>
    </joint>
    <link name='left_elbow'>
      <pose frame=''>0.595 0.5 1.0225 0 -0 0</pose>
      <inertial>
        <pose frame=''>0 0 -0.23375 0 -0 0</pose>
        <mass>10</mass>
        <inertia>
          <ixx>0.0712969</ixx>
          <ixy>0</ixy>
          <ixz>0</ixz>
          <iyy>0.0712969</iyy>
          <iyz>0</iyz>
          <izz>0</izz>
        </inertia>
      </inertial>
      <collision name='left_elbow_collision'>
        <pose frame=''>0 0 0 0 -0 0</pose>
        <geometry>
          <cylinder>
            <length>0.36</length>
            <radius>0.025</radius>
          </cylinder>
        </geometry>
      </collision>
      <collision name='left_elbow_fixed_joint_lump__left_hand_collision_1'>
        <pose frame=''>0 0 -0.36 0 -0 0</pose>
        <geometry>
          <sphere>
            <radius>0.02</radius>
          </sphere>
        </geometry>
      </collision>
      <visual name='left_elbow_visual'>
        <pose frame=''>0 0 -0.185 0 -0 0</pose>
        <geometry>
          <cylinder>
            <length>0.36</length>
            <radius>0.025</radius>
          </cylinder>
        </geometry>
      </visual>
      <visual name='left_elbow_fixed_joint_lump__left_hand_visual_1'>
        <pose frame=''>0 0 -0.38 0 -0 0</pose>
        <geometry>
          <sphere>
            <radius>0.02</radius>
          </sphere>
        </geometry>
      </visual>
    </link>
    <joint name='left_elbow_1' type='revolute'>
      <child>left_elbow</child>
      <parent>left_shoulder</parent>
      <axis>
        <xyz>1 0 0</xyz>
        <limit>
          <lower>-1.57</lower>
          <upper>0</upper>
          <effort>30</effort>
          <velocity>1</velocity>
        </limit>
        <dynamics>
          <spring_reference>0</spring_reference>
          <spring_stiffness>0</spring_stiffness>
        </dynamics>
        <use_parent_model_frame>1</use_parent_model_frame>
      </axis>
    </joint>
    <link name='right_hip'>
      <pose frame=''>0 0 0 0 -0 0</pose>
      <inertial>
        <pose frame=''>0.75 0.5 0.655 0 -0 0</pose>
        <mass>12.5</mass>
        <inertia>
          <ixx>0</ixx>
          <ixy>0</ixy>
          <ixz>0</ixz>
          <iyy>0</iyy>
          <iyz>0</iyz>
          <izz>0</izz>
        </inertia>
      </inertial>
      <collision name='right_hip_collision'>
        <pose frame=''>0 0 0 0 -0 0</pose>
        <geometry>
          <cylinder>
            <length>0.225</length>
            <radius>0.025</radius>
          </cylinder>
        </geometry>
      </collision>
      <visual name='right_hip_visual'>
        <pose frame=''>0.75 0.5 0.655 0 -0 0</pose>
        <geometry>
          <cylinder>
            <length>0.225</length>
            <radius>0.025</radius>
          </cylinder>
        </geometry>
      </visual>
    </link>
    <joint name='right_hip_1' type='revolute'>
      <child>right_hip</child>
      <parent>torso</parent>
      <axis>
        <xyz>1 0 0</xyz>
        <limit>
          <lower>-1e+16</lower>
          <upper>1e+16</upper>
        </limit>
        <dynamics>
          <spring_reference>0</spring_reference>
          <spring_stiffness>0</spring_stiffness>
        </dynamics>
        <use_parent_model_frame>1</use_parent_model_frame>
      </axis>
    </joint>
    <link name='right_knee'>
      <pose frame=''>0 0 0 0 -0 0</pose>
      <inertial>
        <pose frame=''>0.75 0.5 0.34 0 -0 0</pose>
        <mass>7.5</mass>
        <inertia>
          <ixx>0</ixx>
          <ixy>0</ixy>
          <ixz>0</ixz>
          <iyy>0</iyy>
          <iyz>0</iyz>
          <izz>0</izz>
        </inertia>
      </inertial>
      <collision name='right_knee_collision'>
        <pose frame=''>0 0 0 0 -0 0</pose>
        <geometry>
          <cylinder>
            <length>0.4</length>
            <radius>0.025</radius>
          </cylinder>
        </geometry>
      </collision>
      <visual name='right_knee_visual'>
        <pose frame=''>0.75 0.5 0.34 0 -0 0</pose>
        <geometry>
          <cylinder>
            <length>0.4</length>
            <radius>0.025</radius>
          </cylinder>
        </geometry>
      </visual>
    </link>
    <joint name='right_knee_1' type='revolute'>
      <child>right_knee</child>
      <parent>right_hip</parent>
      <axis>
        <xyz>1 0 0</xyz>
        <limit>
          <lower>-1e+16</lower>
          <upper>1e+16</upper>
        </limit>
        <dynamics>
          <spring_reference>0</spring_reference>
          <spring_stiffness>0</spring_stiffness>
        </dynamics>
        <use_parent_model_frame>1</use_parent_model_frame>
      </axis>
    </joint>
    <link name='right_foot'>
      <pose frame=''>0 0 0 0 -0 0</pose>
      <inertial>
        <pose frame=''>0.75 0.5 0.095 0 -0 0</pose>
        <mass>2.5</mass>
        <inertia>
          <ixx>0</ixx>
          <ixy>0</ixy>
          <ixz>0</ixz>
          <iyy>0</iyy>
          <iyz>0</iyz>
          <izz>0</izz>
        </inertia>
      </inertial>
      <collision name='right_foot_collision'>
        <pose frame=''>0 0 0 0 -0 0</pose>
        <geometry>
          <box>
            <size>0.02 0.02 0.08</size>
          </box>
        </geometry>
      </collision>
      <visual name='right_foot_visual'>
        <pose frame=''>0.75 0.5 0.095 0 -0 0</pose>
        <geometry>
          <box>
            <size>0.02 0.02 0.08</size>
          </box>
        </geometry>
      </visual>
    </link>
    <joint name='right_foot_1' type='revolute'>
      <child>right_foot</child>
      <parent>right_knee</parent>
      <axis>
        <xyz>1 0 0</xyz>
        <limit>
          <lower>-1e+16</lower>
          <upper>1e+16</upper>
        </limit>
        <dynamics>
          <spring_reference>0</spring_reference>
          <spring_stiffness>0</spring_stiffness>
        </dynamics>
        <use_parent_model_frame>1</use_parent_model_frame>
      </axis>
    </joint>
    <link name='right_shoulder'>
      <pose frame=''>0.805 0.5 1.1475 -1.57 0 0</pose>
      <inertial>
        <pose frame=''>0 0 -0.0625 0 -0 0</pose>
        <mass>12.5</mass>
        <inertia>
          <ixx>0</ixx>
          <ixy>0</ixy>
          <ixz>0</ixz>
          <iyy>0</iyy>
          <iyz>0</iyz>
          <izz>0</izz>
        </inertia>
      </inertial>
      <collision name='right_shoulder_collision'>
        <pose frame=''>0 0 0 0 -0 0</pose>
        <geometry>
          <cylinder>
            <length>0.125</length>
            <radius>0.025</radius>
          </cylinder>
        </geometry>
      </collision>
      <visual name='right_shoulder_visual'>
        <pose frame=''>0 0 -0.0625 0 -0 0</pose>
        <geometry>
          <cylinder>
            <length>0.125</length>
            <radius>0.025</radius>
          </cylinder>
        </geometry>
      </visual>
    </link>
    <joint name='right_shoulder_1' type='revolute'>
      <child>right_shoulder</child>
      <parent>torso</parent>
      <axis>
        <xyz>1 0 0</xyz>
        <limit>
          <lower>-3.14</lower>
          <upper>3.14</upper>
          <effort>30</effort>
          <velocity>1</velocity>
        </limit>
        <dynamics>
          <spring_reference>0</spring_reference>
          <spring_stiffness>0</spring_stiffness>
        </dynamics>
        <use_parent_model_frame>1</use_parent_model_frame>
      </axis>
    </joint>
    <link name='right_elbow'>
      <pose frame=''>0.805 0.375 1.1474 -1.57 0 0</pose>
      <inertial>
        <pose frame=''>0 0 -0.23375 0 -0 0</pose>
        <mass>10</mass>
        <inertia>
          <ixx>0.0712969</ixx>
          <ixy>0</ixy>
          <ixz>0</ixz>
          <iyy>0.0712969</iyy>
          <iyz>0</iyz>
          <izz>0</izz>
        </inertia>
      </inertial>
      <collision name='right_elbow_collision'>
        <pose frame=''>0 0 0 0 -0 0</pose>
        <geometry>
          <cylinder>
            <length>0.36</length>
            <radius>0.025</radius>
          </cylinder>
        </geometry>
      </collision>
      <collision name='right_elbow_fixed_joint_lump__right_hand_collision_1'>
        <pose frame=''>0 0 -0.36 0 -0 0</pose>
        <geometry>
          <sphere>
            <radius>0.02</radius>
          </sphere>
        </geometry>
      </collision>
      <visual name='right_elbow_visual'>
        <pose frame=''>0 0 -0.185 0 -0 0</pose>
        <geometry>
          <cylinder>
            <length>0.36</length>
            <radius>0.025</radius>
          </cylinder>
        </geometry>
      </visual>
      <visual name='right_elbow_fixed_joint_lump__right_hand_visual_1'>
        <pose frame=''>0 0 -0.38 0 -0 0</pose>
        <geometry>
          <sphere>
            <radius>0.02</radius>
          </sphere>
        </geometry>
      </visual>
    </link>
    <joint name='right_elbow_1' type='revolute'>
      <child>right_elbow</child>
      <parent>right_shoulder</parent>
      <axis>
        <xyz>1 0 0</xyz>
        <limit>
          <lower>-1.57</lower>
          <upper>0</upper>
          <effort>30</effort>
          <velocity>1</velocity>
        </limit>
        <dynamics>
          <spring_reference>0</spring_reference>
          <spring_stiffness>0</spring_stiffness>
        </dynamics>
        <use_parent_model_frame>1</use_parent_model_frame>
      </axis>
    </joint>
  </model>
</sdf>

